<?xml version="1.0" ?>
<!--This file contains the SDF model of a KUKA iiwa robot with a wsg50 gripper.
    It has been produced from the varients in //third_party/robotics/models.
    Note:  This file is temporary, and should be deleted once Bullet supports
    importing models in SDF.  Also, this file has been specialized for Bullet,
    because the mass of the base link has been set to 0, as needed by Bullet.
    Note:  All of the gripper link poses have been adjusted in the z direction
    to achieve a reasonable position of the gripper relative to the arm.
    Note: The joint names for the KUKA have been changed to J0, J1, etc. -->
    <!--There is problem with the kuka mesh and everytime i use it gazebo crashes so I am gonna comment that part-->


<sdf version='1.6'>
  <model name="kuka_handlit">
    <link name = "world">
        <pose frame=''>0 0 0 0 0 0</pose>
        <inertial>
            <pose frame=''>0 0 0.0 0 0 0</pose>
            <mass>0.0</mass>
            <inertia>
                <ixx>0.</ixx>
                <ixy>0</ixy>
                <ixz>0</ixz>
                <iyy>0.</iyy>
                <iyz>0</iyz>
                <izz>0.</izz>
            </inertia>
        </inertial>
    </link>

    <joint name="forearm_world" type="fixed">
        <child>forearm</child>
        <parent>world</parent>
    </joint>

    <!--Hand-->


    <link name ="forearm" >
        <pose frame=''>0 0 0 0 0 1.5707963267948966</pose>
        <inertial>
            <pose frame=''>0 0 0.09 0 0 0</pose>
            <mass>1.8</mass>
            <inertia>
                <ixx>0.108</ixx>
                <ixy>0</ixy>
                <ixz>0</ixz>
                <iyy>0.108</iyy>
                <iyz>0</iyz>
                <izz>0.054</izz>
            </inertia>
        </inertial>

        <visual name='visual_forearm_link'>

            <geometry>
                <mesh>
                    <scale>1 1 1</scale>
                    <uri>/home/mamad/FingersFamily/fingers/fingers/envs/model/meshes/forearm_lite.dae</uri>
                </mesh>
            </geometry>
            <material>
                <ambient>0.5754116717537817 0.7716046889457415 0.37706706785828525 1</ambient>
                <diffuse>0.6915714481023189 0.34924191122629833 0.6770772716833559 1</diffuse>
                <specular>0.30572372141415816 0.9494339252653534 0.07101594794821875 1</specular>
                <emissive>0 0 0 0</emissive>
            </material>
        </visual>
        <collision name='collision_forearm_link'>
        
            <geometry>
                <mesh>
                    <scale>1 1 1</scale>
                    <uri>/home/mamad/FingersFamily/fingers/fingers/envs/model/meshes/forearm_lite.dae</uri>
                </mesh>
            </geometry>
        </collision>
    </link>

    <link name = "palm">
        <pose frame=''>0 -0.015 0.149 -0.6981317007977318 0 0</pose>
        <inertial>
            <pose frame=''>0 0 0.035 0 0 0</pose>
            <mass>0.3</mass>
            <inertia>
                <ixx>0.0003581</ixx>
                <ixy>0</ixy>
                <ixz>0</ixz>
                <iyy>0.0005287</iyy>
                <iyz>0</iyz>
                <izz>0.000191</izz>
            </inertia>
        </inertial>
        
        <visual name='visual_palm_link'>

            <geometry>
                <mesh>
                    <scale>-0.001 0.001 0.001</scale>
                    <uri>/home/mamad/FingersFamily/fingers/fingers/envs/model/meshes/palm2.dae</uri>
                </mesh>
            </geometry>
            <material>
                <ambient>0.8617235850181105 0.9073861212462425 0.9917987732342469 1</ambient>
                <diffuse>0.20242469635451865 0.9335463391665796 0.3878136898154644 1</diffuse>
                <specular>0.5228816701928729 0.352125167838941 0.9535384675717484 1</specular>
                <emissive>0 0 0 0</emissive>
            </material>
        </visual>
        <collision name="collision_palm_link">

            <geometry>
                <mesh>
                    <scale>-0.001 0.001 0.001</scale>
                <uri>/home/mamad/FingersFamily/fingers/fingers/envs/model/meshes/palm2_c.dae</uri>
            </mesh>
            </geometry>
        </collision>


        
    </link>
    <joint name="palm_forearm" type="fixed">
        <child>palm</child>
        <parent>forearm</parent>
        <axis>

            <xyz>0 -1 0</xyz>
         </axis>
    </joint>  

    
    <link name = "palm_fake">

        <pose frame=''>-0.01 0.020909000000000004 0.1889 -0.6981317007977318 0 0</pose>
        <inertial>
            <pose frame=''>0 0 0.0 0 0 0</pose>
            <mass>1.0e-85</mass>
            <inertia>
                <ixx>0.0</ixx>
                <ixy>0</ixy>
                <ixz>0</ixz>
                <iyy>0.0</iyy>
                <iyz>0</iyz>
                <izz>0.0</izz>
            </inertia>
        </inertial>
        <visual name='visual_palm_fake'>
            <geometry>
                <sphere>
                <radius>0.01</radius>
                </sphere>
            </geometry>
            <material>
                <ambient>0.5672216218105076 0.531815859282997 0.5801439037594547 1</ambient>
                <diffuse>0.5464167892541046 0.6932951350253517 0.22253023363722557 1</diffuse>
                <specular>0.9022550019258972 0.9029306286118689 0.5969458319897258 1</specular>
                <emissive>0 0 0 0</emissive>
            </material>
        </visual>
    </link>

    <joint name="palm_palm_fake" type="fixed">
        <child>palm_fake</child>
        <parent>palm</parent>
        <axis>

            <xyz>0 -1 0</xyz>
         </axis>
    </joint>  

    

        

            <link name = "knuckle_FF">

                <pose frame=''>-0.033 0.0461 0.22177 -0.698132 0 0</pose>
                <inertial>
                    <pose frame=''>0 0 0 0 0 0</pose>
                    <mass>0.008</mass>
                    <inertia>
                        <ixx>2.6e-07</ixx>
                        <ixy>0</ixy>
                        <ixz>0</ixz>
                        <iyy>2.6e-07</iyy>
                        <iyz>0</iyz>
                        <izz>3.2e-07</izz>
                    </inertia>
                </inertial>

                <visual name='visual_knuckle_link_FF'>

                    <geometry>
                        <mesh>
                            <scale>0.001 0.001 0.001</scale>
                            <uri>/home/mamad/FingersFamily/fingers/fingers/envs/model/meshes/knuckle.dae</uri>
                        </mesh>
                    </geometry>
                    <material>
                        <ambient>0.28261207138031363 0.455954916623842 0.10392148755768671 1</ambient>
                        <diffuse>0.9872124893610262 0.8834534207504836 0.581534735370712 1</diffuse>
                        <specular>0.1501388698296744 0.22535131063107539 0.16613290175781736 1</specular>
                        <emissive>0 0 0 0</emissive>
                    </material>
                </visual>
                <collision name='collision_knuckle_link_FF'>
                    <geometry>
                    <mesh>
                        <scale>0.001 0.001 0.001</scale>
                        <uri>/home/mamad/FingersFamily/fingers/fingers/envs/model/meshes/knuckle.dae</uri>
                    </mesh>
                </geometry>
                </collision>
            </link>
            <link name = "proximal_FF">
                <pose frame=''>-0.033 0.0461 0.22177 -0.698132 0 0</pose>
                <inertial>
                    <pose frame=''>0 0 0.0225 0 0 0</pose>
                    <mass>0.03</mass>
                    <inertia>
                        <ixx>9.8e-06</ixx>
                        <ixy>0</ixy>
                        <ixz>0</ixz>
                        <iyy>1.0e-05</iyy>
                        <iyz>0</iyz>
                        <izz>1.8e-06</izz>
                    </inertia>
                </inertial>

                <visual name='visual_proximal_link_FF'>

                    <geometry>
                        <mesh>
                            <scale>0.001 0.001 0.001</scale>
                            <uri>/home/mamad/FingersFamily/fingers/fingers/envs/model/meshes/F3.dae</uri>
                        </mesh>
                    </geometry>
                    <material>
                        <ambient>0.6355904459755474 0.035505729373125794 0.02579945392944838 1</ambient>
                        <diffuse>0.9401504291860685 0.7097012469844503 0.520749350258856 1</diffuse>
                        <specular>0.27062474380609114 0.5282690266573382 0.11287716232693379 1</specular>
                        <emissive>0 0 0 0</emissive>
                    </material>
                </visual>
                <collision name='collision_proximal_link_FF'>
                    <geometry>
                    <mesh>
                        <scale>0.001 0.001 0.001</scale>
                        <uri>/home/mamad/FingersFamily/fingers/fingers/envs/model/meshes/F3_c.dae</uri>
                    </mesh>
                </geometry>
                </collision>
            </link>
            <link name = "middle_FF">
                <pose frame=''>-0.033 0.07499 0.256246 -0.698132 0 0</pose>
                <inertial>
                    <pose frame=''>0 0 0.0125 0 0 0</pose>
                    <mass>0.017</mass>
                    <inertia>
                        <ixx>2.6e-06</ixx>
                        <ixy>0</ixy>
                        <ixz>0</ixz>
                        <iyy>2.7e-06</iyy>
                        <iyz>0</iyz>
                        <izz>8.7e-07</izz>
                    </inertia>
                </inertial>

                <visual name='visual_middle_link_FF'>

                    <geometry>
                        <mesh>
                            <scale>0.001 0.001 0.001</scale>
                            <uri>/home/mamad/FingersFamily/fingers/fingers/envs/model/meshes/F2.dae</uri>
                        </mesh>
                    </geometry>
                    <material>
                        <ambient>0.5432111367938489 0.003959905307054923 0.7198429415997502 1</ambient>
                        <diffuse>0.6869278973073281 0.4371367991163837 0.1245958506733017 1</diffuse>
                        <specular>0.22270866134125467 0.3135598037086046 0.0805707520988641 1</specular>
                        <emissive>0 0 0 0</emissive>
                    </material>
                </visual>
                <collision name='collision_middle_link_FF'>
                    <geometry>
                        <mesh>
                            <scale>0.001 0.001 0.001</scale>
                            <uri>/home/mamad/FingersFamily/fingers/fingers/envs/model/meshes/F2_c.dae</uri>
                        </mesh>
                    </geometry>
                </collision>
            </link>
            <link name =  "distal_FF">
                <pose frame=''>-0.033 0.09106 0.275397 -0.698132 0 0</pose>
                <inertial>
                    <pose frame=''>0 0 0.012 0 0 0</pose>
                    <mass>0.012</mass>
                    <inertia>
                        <ixx>9.4e-07</ixx>
                        <ixy>0</ixy>
                        <ixz>0</ixz>
                        <iyy>1.1e-06</iyy>
                        <iyz>0</iyz>
                        <izz>5.3e-07</izz>
                    </inertia>
                </inertial>

                <visual name='visual_distal_link_FF'>

                    <geometry>
                        <mesh>
                            <scale>0.001 0.001 0.001</scale>
                            <uri>/home/mamad/FingersFamily/fingers/fingers/envs/model/meshes/F1.dae</uri>
                        </mesh>
                    </geometry>
                    <material>
                        <ambient>0.9827593262901041 0.3740104402355977 0.9803643930592053 1</ambient>
                        <diffuse>0.012847796513689391 0.3004337722608895 0.07215278011858828 1</diffuse>
                        <specular>0.881566694390308 0.6813541705832624 0.7065699105432218 1</specular>
                        <emissive>0 0 0 0</emissive>
                    </material>
                </visual>
                <collision name='collision_distal_link_FF'>
                    <geometry>
                        <mesh>
                            <scale>0.001 0.001 0.001</scale>
                            <uri>/home/mamad/FingersFamily/fingers/fingers/envs/model/meshes/F1.dae</uri>
                        </mesh>
                    </geometry>
                </collision>
            </link>

            <link name = "fingertip_FF">
                <!-- This link is for visulaization only-->
                <pose frame=''>-0.033 0.1078 0.29529700000000003 -0.698132 0 0</pose>
                <inertial>
                    <pose frame=''>0 0 0.0 0 0 0</pose>
                    <mass>1.0e-94</mass>
                    <inertia>
                        <ixx>0.0</ixx>
                        <ixy>0</ixy>
                        <ixz>0</ixz>
                        <iyy>0.0</iyy>
                        <iyz>0</iyz>
                        <izz>0.0</izz>
                    </inertia>
                </inertial>
                <visual name='visual_fingertip'>
                    <geometry>
                        <sphere>
                        <radius>0.005</radius>
                        </sphere>
                    </geometry>
                    <material>
                        <ambient>0.5672216218105076 0.531815859282997 0.5801439037594547 1</ambient>
                        <diffuse>0.5464167892541046 0.6932951350253517 0.22253023363722557 1</diffuse>
                        <specular>0.9022550019258972 0.9029306286118689 0.5969458319897258 1</specular>
                        <emissive>0 0 0 0</emissive>
                    </material>
                </visual>
            </link>

            
                
                <joint name="J3_FF" type="revolute">
                    <child>proximal_FF</child>
                    <parent>knuckle_FF</parent>

                    <axis>
                        <xyz>1 0 0</xyz>
                        <limit>
                            <lower>0 </lower>
                            <upper>1.5708 </upper>
                            <effort>2.0 </effort>
                            <velocity>2.0 </velocity>
                        </limit>
                        <dynamics>
                            <damping>0.1</damping>
                            <friction>0</friction>
                            <spring_reference>0</spring_reference>
                            <spring_stiffness>0</spring_stiffness>
                        </dynamics>
                    </axis>
                </joint>
            
                
                <joint name="J2_FF" type="revolute">
                    <child>middle_FF</child>
                    <parent>proximal_FF</parent>

                    <axis>
                        <xyz>1 0 0</xyz>
                        <limit>
                            <lower>0 </lower>
                            <upper>1.5708 </upper>
                            <effort>2.0 </effort>
                            <velocity>2.0 </velocity>
                        </limit>
                        <dynamics>
                            <damping>0.1</damping>
                            <friction>0</friction>
                            <spring_reference>0</spring_reference>
                            <spring_stiffness>0</spring_stiffness>
                        </dynamics>
                    </axis>
                </joint>
            
                
                <joint name="J1_FF" type="revolute">
                    <child>distal_FF</child>
                    <parent>middle_FF</parent>

                    <axis>
                        <xyz>1 0 0</xyz>
                        <limit>
                            <lower>0 </lower>
                            <upper>1.5708 </upper>
                            <effort>2.0 </effort>
                            <velocity>2.0 </velocity>
                        </limit>
                        <dynamics>
                            <damping>0.1</damping>
                            <friction>0</friction>
                            <spring_reference>0</spring_reference>
                            <spring_stiffness>0</spring_stiffness>
                        </dynamics>
                    </axis>
                </joint>
            
        <joint name='J4_FF' type="revolute">
            <child>knuckle_FF</child>
            <parent>palm</parent>

            <axis>
                <xyz>0 0.766044 -0.642788</xyz>
                <limit>
                    <lower>-0.349066 </lower>
                    <upper>0.349066 </upper>
                    <effort>2.0 </effort>
                    <velocity>2.0 </velocity>
                </limit>
                <dynamics>
                    <damping>0.1</damping>
                    <friction>0</friction>
                    <spring_reference>0</spring_reference>
                    <spring_stiffness>0</spring_stiffness>
                </dynamics>
            </axis>
        </joint>
        <joint name="J0_FF" type="fixed">
            <child>fingertip_FF</child>
            <parent>distal_FF</parent>
            <axis>

                <xyz>0 -1 0</xyz>
             </axis>
        </joint>

        

                
    
 
    

    

         
   

            <link name =  "ws_FF">
                <pose frame=''>-0.033 0.018000000000000002 0.269 -1.2217304763960306 0.0 0.0</pose>
                <inertial>
                    <pose frame=''>0 0 0.09 0 0 0</pose>
                    <mass>1.8</mass>
                    <inertia>
                        <ixx>0.108</ixx>
                        <ixy>0</ixy>
                        <ixz>0</ixz>
                        <iyy>0.108</iyy>
                        <iyz>0</iyz>
                        <izz>0.054</izz>
                    </inertia>
                </inertial>

                <visual name='visual_ws_FF'>

                    <geometry>
                        <mesh>
                             <scale>0.0015 0.0015 0.0015</scale>
                            <uri>/home/mamad/FingersFamily/fingers/fingers/envs/model/meshes/finger_ws.dae</uri>
                        </mesh>
                    </geometry>
                    <material>
                        <ambient>0.44140625 0.27734375 0.203125 0.7</ambient>
                        <diffuse>0.44140625 0.27734375 0.203125 0.7</diffuse>
                        <specular>0.44140625 0.27734375 0.203125 0.7</specular>
                        <emissive>0 0 0 0</emissive>
                    </material>
                </visual>
            </link>

            <joint name = "ws_FF"  type ="fixed">
               <child>ws_FF</child>
                <parent>palm</parent>
                <axis>
                    <xyz></xyz>
                </axis>
            </joint>

          
 
    
   
   
    
  </model>

</sdf>