<?xml version="1.0" ?>
<!--This file contains the SDF model of a KUKA iiwa robot with a wsg50 gripper.
    It has been produced from the varients in //third_party/robotics/models.
    Note:  This file is temporary, and should be deleted once Bullet supports
    importing models in SDF.  Also, this file has been specialized for Bullet,
    because the mass of the base link has been set to 0, as needed by Bullet.
    Note:  All of the gripper link poses have been adjusted in the z direction
    to achieve a reasonable position of the gripper relative to the arm.
    Note: The joint names for the KUKA have been changed to J0, J1, etc. -->
    <!--There is problem with the kuka mesh and everytime i use it gazebo crashes so I am gonna comment that part-->


<sdf version='1.6'>
  <model name="kuka_handlit">
    <link name = "world">
        <pose frame=''>0 0 0 0 0 0</pose>
        <inertial>
            <pose frame=''>0 0 0.0 0 0 0</pose>
            <mass>0.0</mass>
            <inertia>
                <ixx>0.</ixx>
                <ixy>0</ixy>
                <ixz>0</ixz>
                <iyy>0.</iyy>
                <iyz>0</iyz>
                <izz>0.</izz>
            </inertia>
        </inertial>
    </link>

    <joint name="forearm_world" type="fixed">
        <child>forearm</child>
        <parent>world</parent>
    </joint>

    <!--Hand-->


    <link name ="forearm" >
        <pose frame=''>0 0 0 0 0 1.5707963267948966</pose>
        <inertial>
            <pose frame=''>0 0 0.09 0 0 0</pose>
            <mass>1.8</mass>
            <inertia>
                <ixx>0.108</ixx>
                <ixy>0</ixy>
                <ixz>0</ixz>
                <iyy>0.108</iyy>
                <iyz>0</iyz>
                <izz>0.054</izz>
            </inertia>
        </inertial>

        <visual name='visual_forearm_link'>

            <geometry>
                <mesh>
                    <scale>1 1 1</scale>
                    <uri>/home/mamad/FingersFamily/fingers/fingers/envs/model/meshes/forearm_lite.dae</uri>
                </mesh>
            </geometry>
            <material>
                <ambient>0.9177037975548559 0.20250857898418717 0.4926609240008525 1</ambient>
                <diffuse>0.8305328856669328 0.7741620256788819 0.3880254358185907 1</diffuse>
                <specular>0.5794980039650286 0.7160539054039803 0.35035733084037946 1</specular>
                <emissive>0 0 0 0</emissive>
            </material>
        </visual>
        <collision name='collision_forearm_link'>
        
            <geometry>
                <mesh>
                    <scale>1 1 1</scale>
                    <uri>/home/mamad/FingersFamily/fingers/fingers/envs/model/meshes/forearm_lite.dae</uri>
                </mesh>
            </geometry>
        </collision>
    </link>

    <link name = "palm">
        <pose frame=''>0 -0.015 0.149 -0.6981317007977318 0 0</pose>
        <inertial>
            <pose frame=''>0 0 0.035 0 0 0</pose>
            <mass>0.3</mass>
            <inertia>
                <ixx>0.0003581</ixx>
                <ixy>0</ixy>
                <ixz>0</ixz>
                <iyy>0.0005287</iyy>
                <iyz>0</iyz>
                <izz>0.000191</izz>
            </inertia>
        </inertial>
        
        <visual name='visual_palm_link'>

            <geometry>
                <mesh>
                    <scale>-0.001 0.001 0.001</scale>
                    <uri>/home/mamad/FingersFamily/fingers/fingers/envs/model/meshes/palm2.dae</uri>
                </mesh>
            </geometry>
            <material>
                <ambient>0.6368911122795378 0.8679221117038266 0.09714114327819634 1</ambient>
                <diffuse>0.8563641811519251 0.3803841263615947 0.4692554695376818 1</diffuse>
                <specular>0.26525769568900126 0.14924141186433437 0.7716756730265665 1</specular>
                <emissive>0 0 0 0</emissive>
            </material>
        </visual>
        <collision name="collision_palm_link">

            <geometry>
                <mesh>
                    <scale>-0.001 0.001 0.001</scale>
                <uri>/home/mamad/FingersFamily/fingers/fingers/envs/model/meshes/palm2_c.dae</uri>
            </mesh>
            </geometry>
        </collision>


        
    </link>
    <joint name="palm_forearm" type="fixed">
        <child>palm</child>
        <parent>forearm</parent>
        <axis>

            <xyz>0 -1 0</xyz>
         </axis>
    </joint>  

    
    <link name = "palm_fake">

        <pose frame=''>-0.01 0.020909000000000004 0.1889 -0.6981317007977318 0 0</pose>
        <inertial>
            <pose frame=''>0 0 0.0 0 0 0</pose>
            <mass>1.0e-85</mass>
            <inertia>
                <ixx>0.0</ixx>
                <ixy>0</ixy>
                <ixz>0</ixz>
                <iyy>0.0</iyy>
                <iyz>0</iyz>
                <izz>0.0</izz>
            </inertia>
        </inertial>
        <visual name='visual_palm_fake'>
            <geometry>
                <sphere>
                <radius>0.01</radius>
                </sphere>
            </geometry>
            <material>
                <ambient>0.5672216218105076 0.531815859282997 0.5801439037594547 1</ambient>
                <diffuse>0.5464167892541046 0.6932951350253517 0.22253023363722557 1</diffuse>
                <specular>0.9022550019258972 0.9029306286118689 0.5969458319897258 1</specular>
                <emissive>0 0 0 0</emissive>
            </material>
        </visual>
    </link>

    <joint name="palm_palm_fake" type="fixed">
        <child>palm_fake</child>
        <parent>palm</parent>
        <axis>

            <xyz>0 -1 0</xyz>
         </axis>
    </joint>  

    

        

            <link name = "knuckle_MF">

                <pose frame=''>-0.011000000000000003 0.048636 0.22483799999999998 -0.698132 0 0</pose>
                <inertial>
                    <pose frame=''>0 0 0 0 0 0</pose>
                    <mass>0.008</mass>
                    <inertia>
                        <ixx>2.6e-07</ixx>
                        <ixy>0</ixy>
                        <ixz>0</ixz>
                        <iyy>2.6e-07</iyy>
                        <iyz>0</iyz>
                        <izz>3.2e-07</izz>
                    </inertia>
                </inertial>

                <visual name='visual_knuckle_link_MF'>

                    <geometry>
                        <mesh>
                            <scale>0.001 0.001 0.001</scale>
                            <uri>/home/mamad/FingersFamily/fingers/fingers/envs/model/meshes/knuckle.dae</uri>
                        </mesh>
                    </geometry>
                    <material>
                        <ambient>0.4380312460373046 0.8570487216001078 0.2092087482316023 1</ambient>
                        <diffuse>0.3201713531004535 0.641661090109857 0.8782331327564856 1</diffuse>
                        <specular>0.5803339736013209 0.34694892057445503 0.47577549440367584 1</specular>
                        <emissive>0 0 0 0</emissive>
                    </material>
                </visual>
                <collision name='collision_knuckle_link_MF'>
                    <geometry>
                    <mesh>
                        <scale>0.001 0.001 0.001</scale>
                        <uri>/home/mamad/FingersFamily/fingers/fingers/envs/model/meshes/knuckle.dae</uri>
                    </mesh>
                </geometry>
                </collision>
            </link>
            <link name = "proximal_MF">
                <pose frame=''>-0.011000000000000003 0.048636 0.22483799999999998 -0.698132 0 0</pose>
                <inertial>
                    <pose frame=''>0 0 0.0225 0 0 0</pose>
                    <mass>0.03</mass>
                    <inertia>
                        <ixx>9.8e-06</ixx>
                        <ixy>0</ixy>
                        <ixz>0</ixz>
                        <iyy>1.0e-05</iyy>
                        <iyz>0</iyz>
                        <izz>1.8e-06</izz>
                    </inertia>
                </inertial>

                <visual name='visual_proximal_link_MF'>

                    <geometry>
                        <mesh>
                            <scale>0.001 0.001 0.001</scale>
                            <uri>/home/mamad/FingersFamily/fingers/fingers/envs/model/meshes/F3.dae</uri>
                        </mesh>
                    </geometry>
                    <material>
                        <ambient>0.18935228117793623 0.609371857823335 0.11317165114581718 1</ambient>
                        <diffuse>0.33367292265347825 0.08466647470219346 0.3667121766051191 1</diffuse>
                        <specular>0.7559303931552338 0.936034846298031 0.08258627974290245 1</specular>
                        <emissive>0 0 0 0</emissive>
                    </material>
                </visual>
                <collision name='collision_proximal_link_MF'>
                    <geometry>
                    <mesh>
                        <scale>0.001 0.001 0.001</scale>
                        <uri>/home/mamad/FingersFamily/fingers/fingers/envs/model/meshes/F3_c.dae</uri>
                    </mesh>
                </geometry>
                </collision>
            </link>
            <link name = "middle_MF">
                <pose frame=''>-0.011000000000000003 0.077526 0.259314 -0.698132 0 0</pose>
                <inertial>
                    <pose frame=''>0 0 0.0125 0 0 0</pose>
                    <mass>0.017</mass>
                    <inertia>
                        <ixx>2.6e-06</ixx>
                        <ixy>0</ixy>
                        <ixz>0</ixz>
                        <iyy>2.7e-06</iyy>
                        <iyz>0</iyz>
                        <izz>8.7e-07</izz>
                    </inertia>
                </inertial>

                <visual name='visual_middle_link_MF'>

                    <geometry>
                        <mesh>
                            <scale>0.001 0.001 0.001</scale>
                            <uri>/home/mamad/FingersFamily/fingers/fingers/envs/model/meshes/F2.dae</uri>
                        </mesh>
                    </geometry>
                    <material>
                        <ambient>0.6851658643259362 0.16346760434753604 0.9248079836685795 1</ambient>
                        <diffuse>0.3362455599564379 0.40942716804535184 0.8406075012659154 1</diffuse>
                        <specular>0.16189555552661516 0.8468317781011621 0.5286061699748765 1</specular>
                        <emissive>0 0 0 0</emissive>
                    </material>
                </visual>
                <collision name='collision_middle_link_MF'>
                    <geometry>
                        <mesh>
                            <scale>0.001 0.001 0.001</scale>
                            <uri>/home/mamad/FingersFamily/fingers/fingers/envs/model/meshes/F2_c.dae</uri>
                        </mesh>
                    </geometry>
                </collision>
            </link>
            <link name =  "distal_MF">
                <pose frame=''>-0.011000000000000003 0.093596 0.27846499999999996 -0.698132 0 0</pose>
                <inertial>
                    <pose frame=''>0 0 0.012 0 0 0</pose>
                    <mass>0.012</mass>
                    <inertia>
                        <ixx>9.4e-07</ixx>
                        <ixy>0</ixy>
                        <ixz>0</ixz>
                        <iyy>1.1e-06</iyy>
                        <iyz>0</iyz>
                        <izz>5.3e-07</izz>
                    </inertia>
                </inertial>

                <visual name='visual_distal_link_MF'>

                    <geometry>
                        <mesh>
                            <scale>0.001 0.001 0.001</scale>
                            <uri>/home/mamad/FingersFamily/fingers/fingers/envs/model/meshes/F1.dae</uri>
                        </mesh>
                    </geometry>
                    <material>
                        <ambient>0.6810327756744744 0.167167112788293 0.25040019827127 1</ambient>
                        <diffuse>0.49861838547501314 0.09234131182851302 0.7841848658294804 1</diffuse>
                        <specular>0.4200120364950697 0.134424820747449 0.6367485991482391 1</specular>
                        <emissive>0 0 0 0</emissive>
                    </material>
                </visual>
                <collision name='collision_distal_link_MF'>
                    <geometry>
                        <mesh>
                            <scale>0.001 0.001 0.001</scale>
                            <uri>/home/mamad/FingersFamily/fingers/fingers/envs/model/meshes/F1.dae</uri>
                        </mesh>
                    </geometry>
                </collision>
            </link>

            <link name = "fingertip_MF">
                <!-- This link is for visulaization only-->
                <pose frame=''>-0.011000000000000003 0.110336 0.298365 -0.698132 0 0</pose>
                <inertial>
                    <pose frame=''>0 0 0.0 0 0 0</pose>
                    <mass>1.0e-94</mass>
                    <inertia>
                        <ixx>0.0</ixx>
                        <ixy>0</ixy>
                        <ixz>0</ixz>
                        <iyy>0.0</iyy>
                        <iyz>0</iyz>
                        <izz>0.0</izz>
                    </inertia>
                </inertial>
                <visual name='visual_fingertip'>
                    <geometry>
                        <sphere>
                        <radius>0.005</radius>
                        </sphere>
                    </geometry>
                    <material>
                        <ambient>0.5672216218105076 0.531815859282997 0.5801439037594547 1</ambient>
                        <diffuse>0.5464167892541046 0.6932951350253517 0.22253023363722557 1</diffuse>
                        <specular>0.9022550019258972 0.9029306286118689 0.5969458319897258 1</specular>
                        <emissive>0 0 0 0</emissive>
                    </material>
                </visual>
            </link>

            
                
                <joint name="J3_MF" type="revolute">
                    <child>proximal_MF</child>
                    <parent>knuckle_MF</parent>

                    <axis>
                        <xyz>1 0 0</xyz>
                        <limit>
                            <lower>0 </lower>
                            <upper>1.5708 </upper>
                            <effort>2.0 </effort>
                            <velocity>2.0 </velocity>
                        </limit>
                        <dynamics>
                            <damping>0.1</damping>
                            <friction>0</friction>
                            <spring_reference>0</spring_reference>
                            <spring_stiffness>0</spring_stiffness>
                        </dynamics>
                    </axis>
                </joint>
            
                
                <joint name="J2_MF" type="revolute">
                    <child>middle_MF</child>
                    <parent>proximal_MF</parent>

                    <axis>
                        <xyz>1 0 0</xyz>
                        <limit>
                            <lower>0 </lower>
                            <upper>1.5708 </upper>
                            <effort>2.0 </effort>
                            <velocity>2.0 </velocity>
                        </limit>
                        <dynamics>
                            <damping>0.1</damping>
                            <friction>0</friction>
                            <spring_reference>0</spring_reference>
                            <spring_stiffness>0</spring_stiffness>
                        </dynamics>
                    </axis>
                </joint>
            
                
                <joint name="J1_MF" type="revolute">
                    <child>distal_MF</child>
                    <parent>middle_MF</parent>

                    <axis>
                        <xyz>1 0 0</xyz>
                        <limit>
                            <lower>0 </lower>
                            <upper>1.5708 </upper>
                            <effort>2.0 </effort>
                            <velocity>2.0 </velocity>
                        </limit>
                        <dynamics>
                            <damping>0.1</damping>
                            <friction>0</friction>
                            <spring_reference>0</spring_reference>
                            <spring_stiffness>0</spring_stiffness>
                        </dynamics>
                    </axis>
                </joint>
            
        <joint name='J4_MF' type="revolute">
            <child>knuckle_MF</child>
            <parent>palm</parent>

            <axis>
                <xyz>0 0.766044 -0.642788</xyz>
                <limit>
                    <lower>-0.349066 </lower>
                    <upper>0.349066 </upper>
                    <effort>2.0 </effort>
                    <velocity>2.0 </velocity>
                </limit>
                <dynamics>
                    <damping>0.1</damping>
                    <friction>0</friction>
                    <spring_reference>0</spring_reference>
                    <spring_stiffness>0</spring_stiffness>
                </dynamics>
            </axis>
        </joint>
        <joint name="J0_MF" type="fixed">
            <child>fingertip_MF</child>
            <parent>distal_MF</parent>
            <axis>

                <xyz>0 -1 0</xyz>
             </axis>
        </joint>

        

                
    
 
    

    

         
   

            <link name =  "ws_MF">
                <pose frame=''>-0.011000000000000003 0.020536000000000002 0.27206800000000003 -1.2217304763960306 0.0 0.0</pose>
                <inertial>
                    <pose frame=''>0 0 0.09 0 0 0</pose>
                    <mass>1.8</mass>
                    <inertia>
                        <ixx>0.108</ixx>
                        <ixy>0</ixy>
                        <ixz>0</ixz>
                        <iyy>0.108</iyy>
                        <iyz>0</iyz>
                        <izz>0.054</izz>
                    </inertia>
                </inertial>

                <visual name='visual_ws_MF'>

                    <geometry>
                        <mesh>
                             <scale>0.0015 0.0015 0.0015</scale>
                            <uri>/home/mamad/FingersFamily/fingers/fingers/envs/model/meshes/finger_ws.dae</uri>
                        </mesh>
                    </geometry>
                    <material>
                        <ambient>0.73046875 0.27734375 0.203125 0.7</ambient>
                        <diffuse>0.73046875 0.27734375 0.203125 0.7</diffuse>
                        <specular>0.73046875 0.27734375 0.203125 0.7</specular>
                        <emissive>0 0 0 0</emissive>
                    </material>
                </visual>
            </link>

            <joint name = "ws_MF"  type ="fixed">
               <child>ws_MF</child>
                <parent>palm</parent>
                <axis>
                    <xyz></xyz>
                </axis>
            </joint>

          
 
    
   
   
    
  </model>

</sdf>